{"timestamp": "2025-04-23T16:03:44.244558+00:00", "level": "INFO", "message": "Logging initialized. Log file: logs\\mdt_agent.log", "module": "logger", "function": "setup_logging", "line": 94, "trace_id": "1751c4d2-bae9-4ae1-b679-3c3ba3ea7c6d", "taskName": null}
{"timestamp": "2025-04-23T16:03:44.247644+00:00", "level": "ERROR", "message": "Failed to initialize ChatGoogleGenerativeAI LLM: 'Settings' object has no attribute 'llm_model_name'", "module": "llm", "function": "get_llm", "line": 42, "trace_id": "1751c4d2-bae9-4ae1-b679-3c3ba3ea7c6d", "exception": "Traceback (most recent call last):\n  File \"C:\\Users\\arvin\\OneDrive\\Documents\\Arkus AI - AI Engineer\\Healthcare-Triage-Multi-Agent\\mdt_agent_system\\app\\core\\llm.py\", line 27, in get_llm\n    model=config.llm_model_name,\n          ^^^^^^^^^^^^^^^^^^^^^\n  File \"C:\\Users\\arvin\\AppData\\Roaming\\Python\\Python313\\site-packages\\pydantic\\main.py\", line 994, in __getattr__\n    raise AttributeError(f'{type(self).__name__!r} object has no attribute {item!r}')\nAttributeError: 'Settings' object has no attribute 'llm_model_name'", "taskName": null}
{"timestamp": "2025-04-23T16:03:44.253278+00:00", "level": "ERROR", "message": "Error during LLM initialization: Failed to initialize LLM. Ensure GOOGLE_API_KEY is set correctly and valid. Error: 'Settings' object has no attribute 'llm_model_name'", "module": "llm", "function": "<module>", "line": 84, "trace_id": "1751c4d2-bae9-4ae1-b679-3c3ba3ea7c6d", "exception": "Traceback (most recent call last):\n  File \"C:\\Users\\arvin\\OneDrive\\Documents\\Arkus AI - AI Engineer\\Healthcare-Triage-Multi-Agent\\mdt_agent_system\\app\\core\\llm.py\", line 27, in get_llm\n    model=config.llm_model_name,\n          ^^^^^^^^^^^^^^^^^^^^^\n  File \"C:\\Users\\arvin\\AppData\\Roaming\\Python\\Python313\\site-packages\\pydantic\\main.py\", line 994, in __getattr__\n    raise AttributeError(f'{type(self).__name__!r} object has no attribute {item!r}')\nAttributeError: 'Settings' object has no attribute 'llm_model_name'\n\nDuring handling of the above exception, another exception occurred:\n\nTraceback (most recent call last):\n  File \"C:\\Users\\arvin\\OneDrive\\Documents\\Arkus AI - AI Engineer\\Healthcare-Triage-Multi-Agent\\mdt_agent_system\\app\\core\\llm.py\", line 71, in <module>\n    test_llm = get_llm(callbacks=[logging_callback])\n  File \"C:\\Users\\arvin\\OneDrive\\Documents\\Arkus AI - AI Engineer\\Healthcare-Triage-Multi-Agent\\mdt_agent_system\\app\\core\\llm.py\", line 44, in get_llm\n    raise ValueError(f\"Failed to initialize LLM. Ensure GOOGLE_API_KEY is set correctly and valid. Error: {e}\")\nValueError: Failed to initialize LLM. Ensure GOOGLE_API_KEY is set correctly and valid. Error: 'Settings' object has no attribute 'llm_model_name'", "taskName": null}
{"timestamp": "2025-04-23T16:06:47.746822+00:00", "level": "INFO", "message": "Logging initialized. Log file: logs\\mdt_agent.log", "module": "logger", "function": "setup_logging", "line": 94, "trace_id": "3105e5a4-01a4-49e6-b65e-f3ae294666e0", "taskName": null}
{"timestamp": "2025-04-23T16:06:47.748649+00:00", "level": "ERROR", "message": "Failed to initialize ChatGoogleGenerativeAI LLM: 'Settings' object has no attribute 'llm_model'", "module": "llm", "function": "get_llm", "line": 42, "trace_id": "3105e5a4-01a4-49e6-b65e-f3ae294666e0", "exception": "Traceback (most recent call last):\n  File \"C:\\Users\\arvin\\OneDrive\\Documents\\Arkus AI - AI Engineer\\Healthcare-Triage-Multi-Agent\\mdt_agent_system\\app\\core\\llm.py\", line 27, in get_llm\n    model=config.llm_model,\n          ^^^^^^^^^^^^^^^^\n  File \"C:\\Users\\arvin\\AppData\\Roaming\\Python\\Python313\\site-packages\\pydantic\\main.py\", line 994, in __getattr__\n    raise AttributeError(f'{type(self).__name__!r} object has no attribute {item!r}')\nAttributeError: 'Settings' object has no attribute 'llm_model'", "taskName": null}
{"timestamp": "2025-04-23T16:06:47.752289+00:00", "level": "ERROR", "message": "Error during LLM initialization: Failed to initialize LLM. Ensure GOOGLE_API_KEY is set correctly and valid. Error: 'Settings' object has no attribute 'llm_model'", "module": "llm", "function": "<module>", "line": 84, "trace_id": "3105e5a4-01a4-49e6-b65e-f3ae294666e0", "exception": "Traceback (most recent call last):\n  File \"C:\\Users\\arvin\\OneDrive\\Documents\\Arkus AI - AI Engineer\\Healthcare-Triage-Multi-Agent\\mdt_agent_system\\app\\core\\llm.py\", line 27, in get_llm\n    model=config.llm_model,\n          ^^^^^^^^^^^^^^^^\n  File \"C:\\Users\\arvin\\AppData\\Roaming\\Python\\Python313\\site-packages\\pydantic\\main.py\", line 994, in __getattr__\n    raise AttributeError(f'{type(self).__name__!r} object has no attribute {item!r}')\nAttributeError: 'Settings' object has no attribute 'llm_model'\n\nDuring handling of the above exception, another exception occurred:\n\nTraceback (most recent call last):\n  File \"C:\\Users\\arvin\\OneDrive\\Documents\\Arkus AI - AI Engineer\\Healthcare-Triage-Multi-Agent\\mdt_agent_system\\app\\core\\llm.py\", line 71, in <module>\n    test_llm = get_llm(callbacks=[logging_callback])\n  File \"C:\\Users\\arvin\\OneDrive\\Documents\\Arkus AI - AI Engineer\\Healthcare-Triage-Multi-Agent\\mdt_agent_system\\app\\core\\llm.py\", line 44, in get_llm\n    raise ValueError(f\"Failed to initialize LLM. Ensure GOOGLE_API_KEY is set correctly and valid. Error: {e}\")\nValueError: Failed to initialize LLM. Ensure GOOGLE_API_KEY is set correctly and valid. Error: 'Settings' object has no attribute 'llm_model'", "taskName": null}
{"timestamp": "2025-04-23T16:09:14.084084+00:00", "level": "INFO", "message": "Logging initialized. Log file: logs\\mdt_agent.log", "module": "logger", "function": "setup_logging", "line": 94, "trace_id": "5037a88f-aea7-4881-a29a-6fcabf804244", "taskName": null}
{"timestamp": "2025-04-23T16:09:14.086388+00:00", "level": "ERROR", "message": "Failed to initialize ChatGoogleGenerativeAI LLM: 'Settings' object has no attribute 'google_api_key'", "module": "llm", "function": "get_llm", "line": 42, "trace_id": "5037a88f-aea7-4881-a29a-6fcabf804244", "exception": "Traceback (most recent call last):\n  File \"C:\\Users\\arvin\\OneDrive\\Documents\\Arkus AI - AI Engineer\\Healthcare-Triage-Multi-Agent\\mdt_agent_system\\app\\core\\llm.py\", line 28, in get_llm\n    google_api_key=config.google_api_key,\n                   ^^^^^^^^^^^^^^^^^^^^^\n  File \"C:\\Users\\arvin\\AppData\\Roaming\\Python\\Python313\\site-packages\\pydantic\\main.py\", line 994, in __getattr__\n    raise AttributeError(f'{type(self).__name__!r} object has no attribute {item!r}')\nAttributeError: 'Settings' object has no attribute 'google_api_key'", "taskName": null}
{"timestamp": "2025-04-23T16:09:14.092002+00:00", "level": "ERROR", "message": "Error during LLM initialization: Failed to initialize LLM. Ensure GOOGLE_API_KEY is set correctly and valid. Error: 'Settings' object has no attribute 'google_api_key'", "module": "llm", "function": "<module>", "line": 84, "trace_id": "5037a88f-aea7-4881-a29a-6fcabf804244", "exception": "Traceback (most recent call last):\n  File \"C:\\Users\\arvin\\OneDrive\\Documents\\Arkus AI - AI Engineer\\Healthcare-Triage-Multi-Agent\\mdt_agent_system\\app\\core\\llm.py\", line 28, in get_llm\n    google_api_key=config.google_api_key,\n                   ^^^^^^^^^^^^^^^^^^^^^\n  File \"C:\\Users\\arvin\\AppData\\Roaming\\Python\\Python313\\site-packages\\pydantic\\main.py\", line 994, in __getattr__\n    raise AttributeError(f'{type(self).__name__!r} object has no attribute {item!r}')\nAttributeError: 'Settings' object has no attribute 'google_api_key'\n\nDuring handling of the above exception, another exception occurred:\n\nTraceback (most recent call last):\n  File \"C:\\Users\\arvin\\OneDrive\\Documents\\Arkus AI - AI Engineer\\Healthcare-Triage-Multi-Agent\\mdt_agent_system\\app\\core\\llm.py\", line 71, in <module>\n    test_llm = get_llm(callbacks=[logging_callback])\n  File \"C:\\Users\\arvin\\OneDrive\\Documents\\Arkus AI - AI Engineer\\Healthcare-Triage-Multi-Agent\\mdt_agent_system\\app\\core\\llm.py\", line 44, in get_llm\n    raise ValueError(f\"Failed to initialize LLM. Ensure GOOGLE_API_KEY is set correctly and valid. Error: {e}\")\nValueError: Failed to initialize LLM. Ensure GOOGLE_API_KEY is set correctly and valid. Error: 'Settings' object has no attribute 'google_api_key'", "taskName": null}
{"timestamp": "2025-04-23T16:14:37.405820+00:00", "level": "INFO", "message": "Logging initialized. Log file: logs\\mdt_agent.log", "module": "logger", "function": "setup_logging", "line": 94, "trace_id": "d9abcc1f-b22e-4238-8df4-aff979fc2465", "taskName": null}
{"timestamp": "2025-04-23T16:14:37.409206+00:00", "level": "ERROR", "message": "Failed to initialize ChatGoogleGenerativeAI LLM: 'Settings' object has no attribute 'google_api_key'", "module": "llm", "function": "get_llm", "line": 42, "trace_id": "d9abcc1f-b22e-4238-8df4-aff979fc2465", "exception": "Traceback (most recent call last):\n  File \"C:\\Users\\arvin\\OneDrive\\Documents\\Arkus AI - AI Engineer\\Healthcare-Triage-Multi-Agent\\mdt_agent_system\\app\\core\\llm.py\", line 28, in get_llm\n    google_api_key=config.google_api_key,\n                   ^^^^^^^^^^^^^^^^^^^^^\n  File \"C:\\Users\\arvin\\AppData\\Roaming\\Python\\Python313\\site-packages\\pydantic\\main.py\", line 994, in __getattr__\n    raise AttributeError(f'{type(self).__name__!r} object has no attribute {item!r}')\nAttributeError: 'Settings' object has no attribute 'google_api_key'", "taskName": null}
{"timestamp": "2025-04-23T16:14:37.416586+00:00", "level": "ERROR", "message": "Error during LLM initialization: Failed to initialize LLM. Ensure GOOGLE_API_KEY is set correctly and valid. Error: 'Settings' object has no attribute 'google_api_key'", "module": "llm", "function": "<module>", "line": 84, "trace_id": "d9abcc1f-b22e-4238-8df4-aff979fc2465", "exception": "Traceback (most recent call last):\n  File \"C:\\Users\\arvin\\OneDrive\\Documents\\Arkus AI - AI Engineer\\Healthcare-Triage-Multi-Agent\\mdt_agent_system\\app\\core\\llm.py\", line 28, in get_llm\n    google_api_key=config.google_api_key,\n                   ^^^^^^^^^^^^^^^^^^^^^\n  File \"C:\\Users\\arvin\\AppData\\Roaming\\Python\\Python313\\site-packages\\pydantic\\main.py\", line 994, in __getattr__\n    raise AttributeError(f'{type(self).__name__!r} object has no attribute {item!r}')\nAttributeError: 'Settings' object has no attribute 'google_api_key'\n\nDuring handling of the above exception, another exception occurred:\n\nTraceback (most recent call last):\n  File \"C:\\Users\\arvin\\OneDrive\\Documents\\Arkus AI - AI Engineer\\Healthcare-Triage-Multi-Agent\\mdt_agent_system\\app\\core\\llm.py\", line 71, in <module>\n    test_llm = get_llm(callbacks=[logging_callback])\n  File \"C:\\Users\\arvin\\OneDrive\\Documents\\Arkus AI - AI Engineer\\Healthcare-Triage-Multi-Agent\\mdt_agent_system\\app\\core\\llm.py\", line 44, in get_llm\n    raise ValueError(f\"Failed to initialize LLM. Ensure GOOGLE_API_KEY is set correctly and valid. Error: {e}\")\nValueError: Failed to initialize LLM. Ensure GOOGLE_API_KEY is set correctly and valid. Error: 'Settings' object has no attribute 'google_api_key'", "taskName": null}
{"timestamp": "2025-04-23T16:18:11.494854+00:00", "level": "INFO", "message": "Logging initialized. Log file: logs\\mdt_agent.log", "module": "logger", "function": "setup_logging", "line": 94, "trace_id": "dcc48dc0-5b3a-4a61-bf30-a13096592ab3", "taskName": null}
{"timestamp": "2025-04-23T16:18:11.497319+00:00", "level": "ERROR", "message": "Failed to initialize ChatGoogleGenerativeAI LLM: 'Settings' object has no attribute 'google_api_key'", "module": "llm", "function": "get_llm", "line": 42, "trace_id": "dcc48dc0-5b3a-4a61-bf30-a13096592ab3", "exception": "Traceback (most recent call last):\n  File \"C:\\Users\\arvin\\OneDrive\\Documents\\Arkus AI - AI Engineer\\Healthcare-Triage-Multi-Agent\\mdt_agent_system\\app\\core\\llm.py\", line 28, in get_llm\n    google_api_key=config.google_api_key,\n                   ^^^^^^^^^^^^^^^^^^^^^\n  File \"C:\\Users\\arvin\\AppData\\Roaming\\Python\\Python313\\site-packages\\pydantic\\main.py\", line 994, in __getattr__\n    raise AttributeError(f'{type(self).__name__!r} object has no attribute {item!r}')\nAttributeError: 'Settings' object has no attribute 'google_api_key'", "taskName": null}
{"timestamp": "2025-04-23T16:18:11.503169+00:00", "level": "ERROR", "message": "Error during LLM initialization: Failed to initialize LLM. Ensure GOOGLE_API_KEY is set correctly and valid. Error: 'Settings' object has no attribute 'google_api_key'", "module": "llm", "function": "<module>", "line": 84, "trace_id": "dcc48dc0-5b3a-4a61-bf30-a13096592ab3", "exception": "Traceback (most recent call last):\n  File \"C:\\Users\\arvin\\OneDrive\\Documents\\Arkus AI - AI Engineer\\Healthcare-Triage-Multi-Agent\\mdt_agent_system\\app\\core\\llm.py\", line 28, in get_llm\n    google_api_key=config.google_api_key,\n                   ^^^^^^^^^^^^^^^^^^^^^\n  File \"C:\\Users\\arvin\\AppData\\Roaming\\Python\\Python313\\site-packages\\pydantic\\main.py\", line 994, in __getattr__\n    raise AttributeError(f'{type(self).__name__!r} object has no attribute {item!r}')\nAttributeError: 'Settings' object has no attribute 'google_api_key'\n\nDuring handling of the above exception, another exception occurred:\n\nTraceback (most recent call last):\n  File \"C:\\Users\\arvin\\OneDrive\\Documents\\Arkus AI - AI Engineer\\Healthcare-Triage-Multi-Agent\\mdt_agent_system\\app\\core\\llm.py\", line 71, in <module>\n    test_llm = get_llm(callbacks=[logging_callback])\n  File \"C:\\Users\\arvin\\OneDrive\\Documents\\Arkus AI - AI Engineer\\Healthcare-Triage-Multi-Agent\\mdt_agent_system\\app\\core\\llm.py\", line 44, in get_llm\n    raise ValueError(f\"Failed to initialize LLM. Ensure GOOGLE_API_KEY is set correctly and valid. Error: {e}\")\nValueError: Failed to initialize LLM. Ensure GOOGLE_API_KEY is set correctly and valid. Error: 'Settings' object has no attribute 'google_api_key'", "taskName": null}
{"timestamp": "2025-04-23T16:18:56.722794+00:00", "level": "INFO", "message": "Logging initialized. Log file: logs\\mdt_agent.log", "module": "logger", "function": "setup_logging", "line": 94, "trace_id": "d3f5ed05-77bf-41b4-aaa8-817da338a492", "taskName": null}
{"timestamp": "2025-04-23T16:18:56.726354+00:00", "level": "ERROR", "message": "Failed to initialize ChatGoogleGenerativeAI LLM: 'Settings' object has no attribute 'google_api_key'", "module": "llm", "function": "get_llm", "line": 42, "trace_id": "d3f5ed05-77bf-41b4-aaa8-817da338a492", "exception": "Traceback (most recent call last):\n  File \"C:\\Users\\arvin\\OneDrive\\Documents\\Arkus AI - AI Engineer\\Healthcare-Triage-Multi-Agent\\mdt_agent_system\\app\\core\\llm.py\", line 28, in get_llm\n    google_api_key=config.google_api_key,\n                   ^^^^^^^^^^^^^^^^^^^^^\n  File \"C:\\Users\\arvin\\AppData\\Roaming\\Python\\Python313\\site-packages\\pydantic\\main.py\", line 994, in __getattr__\n    raise AttributeError(f'{type(self).__name__!r} object has no attribute {item!r}')\nAttributeError: 'Settings' object has no attribute 'google_api_key'", "taskName": null}
{"timestamp": "2025-04-23T16:18:56.733889+00:00", "level": "ERROR", "message": "Error during LLM initialization: Failed to initialize LLM. Ensure GOOGLE_API_KEY is set correctly and valid. Error: 'Settings' object has no attribute 'google_api_key'", "module": "llm", "function": "<module>", "line": 84, "trace_id": "d3f5ed05-77bf-41b4-aaa8-817da338a492", "exception": "Traceback (most recent call last):\n  File \"C:\\Users\\arvin\\OneDrive\\Documents\\Arkus AI - AI Engineer\\Healthcare-Triage-Multi-Agent\\mdt_agent_system\\app\\core\\llm.py\", line 28, in get_llm\n    google_api_key=config.google_api_key,\n                   ^^^^^^^^^^^^^^^^^^^^^\n  File \"C:\\Users\\arvin\\AppData\\Roaming\\Python\\Python313\\site-packages\\pydantic\\main.py\", line 994, in __getattr__\n    raise AttributeError(f'{type(self).__name__!r} object has no attribute {item!r}')\nAttributeError: 'Settings' object has no attribute 'google_api_key'\n\nDuring handling of the above exception, another exception occurred:\n\nTraceback (most recent call last):\n  File \"C:\\Users\\arvin\\OneDrive\\Documents\\Arkus AI - AI Engineer\\Healthcare-Triage-Multi-Agent\\mdt_agent_system\\app\\core\\llm.py\", line 71, in <module>\n    test_llm = get_llm(callbacks=[logging_callback])\n  File \"C:\\Users\\arvin\\OneDrive\\Documents\\Arkus AI - AI Engineer\\Healthcare-Triage-Multi-Agent\\mdt_agent_system\\app\\core\\llm.py\", line 44, in get_llm\n    raise ValueError(f\"Failed to initialize LLM. Ensure GOOGLE_API_KEY is set correctly and valid. Error: {e}\")\nValueError: Failed to initialize LLM. Ensure GOOGLE_API_KEY is set correctly and valid. Error: 'Settings' object has no attribute 'google_api_key'", "taskName": null}
{"timestamp": "2025-04-23T16:20:18.689048+00:00", "level": "INFO", "message": "Logging initialized. Log file: logs\\mdt_agent.log", "module": "logger", "function": "setup_logging", "line": 94, "trace_id": "3114525a-db45-4039-9c9a-832854fbb897", "taskName": null}
{"timestamp": "2025-04-23T16:20:18.723337+00:00", "level": "INFO", "message": "Initialized ChatGoogleGenerativeAI LLM with model: gemini-1.5-flash-latest", "module": "llm", "function": "get_llm", "line": 35, "trace_id": "3114525a-db45-4039-9c9a-832854fbb897", "taskName": null}
{"timestamp": "2025-04-23T16:20:18.729131+00:00", "level": "INFO", "message": "LLM Start (Run ID: de03340f-e9aa-4675-919f-0d9a205860d5)", "module": "callbacks", "function": "on_llm_start", "line": 25, "trace_id": "3114525a-db45-4039-9c9a-832854fbb897", "taskName": null, "run_id": "de03340f-e9aa-4675-919f-0d9a205860d5", "parent_run_id": null, "tags": [], "metadata": {"ls_provider": "google_genai", "ls_model_name": "models/gemini-1.5-flash-latest", "ls_model_type": "chat", "ls_temperature": 0.7}, "llm_prompts": ["Human: Explain the concept of a Large Language Model in one sentence."]}
{"timestamp": "2025-04-23T16:20:19.316542+00:00", "level": "INFO", "message": "LLM End (Run ID: de03340f-e9aa-4675-919f-0d9a205860d5)", "module": "callbacks", "function": "on_llm_end", "line": 53, "trace_id": "3114525a-db45-4039-9c9a-832854fbb897", "taskName": null, "run_id": "de03340f-e9aa-4675-919f-0d9a205860d5", "parent_run_id": null, "llm_output": {"prompt_feedback": {"block_reason": 0, "safety_ratings": []}}, "finish_reason": "STOP", "token_usage_input": null, "token_usage_output": null}
